
Lmod is automatically replacing "nvhpc/21.9" with "gcc/11.2.0".


Lmod is automatically replacing "PrgEnv-nvhpc/8.3.3" with "PrgEnv-gnu/8.3.3".


Due to MODULEPATH changes, the following have been reloaded:
  1) cray-mpich/8.1.16

wandb: Currently logged in as: hzheng. Use `wandb login --relogin` to force relogin
wandb: wandb version 0.13.3 is available!  To upgrade, please run:
wandb:  $ pip install wandb --upgrade
wandb: Tracking run with wandb version 0.12.21
wandb: Run data is saved locally in /lus/grand/projects/datascience/hzheng/mlperf-2022/optimized-hpc/cosmoflow/tensorflow/wandb/run-20220913_060600-26ycb9rp
wandb: Run `wandb offline` to turn off syncing.
wandb: Syncing run eager-grass-113
wandb: ‚≠êÔ∏è View project at https://wandb.ai/hzheng/cosmoflow
wandb: üöÄ View run at https://wandb.ai/hzheng/cosmoflow/runs/26ycb9rp
--- Logging error ---
Traceback (most recent call last):
  File "/soft/datascience/conda/2022-07-19/mconda3/lib/python3.8/logging/__init__.py", line 1089, in emit
    self.flush()
  File "/soft/datascience/conda/2022-07-19/mconda3/lib/python3.8/logging/__init__.py", line 1069, in flush
    self.stream.flush()
OSError: [Errno 122] Disk quota exceeded
Call stack:
  File "/soft/datascience/conda/2022-07-19/mconda3/lib/python3.8/threading.py", line 890, in _bootstrap
    self._bootstrap_inner()
  File "/soft/datascience/conda/2022-07-19/mconda3/lib/python3.8/threading.py", line 932, in _bootstrap_inner
    self.run()
  File "/soft/datascience/conda/2022-07-19/mconda3/lib/python3.8/site-packages/wandb/sdk/internal/internal_util.py", line 51, in run
    self._run()
  File "/soft/datascience/conda/2022-07-19/mconda3/lib/python3.8/site-packages/wandb/sdk/internal/internal_util.py", line 102, in _run
    self._process(record)
  File "/soft/datascience/conda/2022-07-19/mconda3/lib/python3.8/site-packages/wandb/sdk/internal/internal.py", line 310, in _process
    self._sm.send(record)
  File "/soft/datascience/conda/2022-07-19/mconda3/lib/python3.8/site-packages/wandb/sdk/internal/sender.py", line 236, in send
    logger.debug(f"send: {record_type}")
Message: 'send: stats'
Arguments: ()
--- Logging error ---
Traceback (most recent call last):
  File "/soft/datascience/conda/2022-07-19/mconda3/lib/python3.8/logging/__init__.py", line 1089, in emit
    self.flush()
  File "/soft/datascience/conda/2022-07-19/mconda3/lib/python3.8/logging/__init__.py", line 1069, in flush
    self.stream.flush()
OSError: [Errno 122] Disk quota exceeded
Call stack:
  File "/soft/datascience/conda/2022-07-19/mconda3/lib/python3.8/threading.py", line 890, in _bootstrap
    self._bootstrap_inner()
  File "/soft/datascience/conda/2022-07-19/mconda3/lib/python3.8/threading.py", line 932, in _bootstrap_inner
    self.run()
  File "/soft/datascience/conda/2022-07-19/mconda3/lib/python3.8/site-packages/wandb/sdk/internal/internal_util.py", line 51, in run
    self._run()
  File "/soft/datascience/conda/2022-07-19/mconda3/lib/python3.8/site-packages/wandb/sdk/internal/internal_util.py", line 102, in _run
    self._process(record)
  File "/soft/datascience/conda/2022-07-19/mconda3/lib/python3.8/site-packages/wandb/sdk/internal/internal.py", line 265, in _process
    self._hm.handle(record)
  File "/soft/datascience/conda/2022-07-19/mconda3/lib/python3.8/site-packages/wandb/sdk/internal/handler.py", line 132, in handle
    handler(record)
  File "/soft/datascience/conda/2022-07-19/mconda3/lib/python3.8/site-packages/wandb/sdk/internal/handler.py", line 140, in handle_request
    logger.debug(f"handle_request: {request_type}")
Message: 'handle_request: stop_status'
Arguments: ()
--- Logging error ---
Traceback (most recent call last):
  File "/soft/datascience/conda/2022-07-19/mconda3/lib/python3.8/logging/__init__.py", line 1089, in emit
    self.flush()
  File "/soft/datascience/conda/2022-07-19/mconda3/lib/python3.8/logging/__init__.py", line 1069, in flush
    self.stream.flush()
OSError: [Errno 122] Disk quota exceeded
Call stack:
  File "/soft/datascience/conda/2022-07-19/mconda3/lib/python3.8/threading.py", line 890, in _bootstrap
    self._bootstrap_inner()
  File "/soft/datascience/conda/2022-07-19/mconda3/lib/python3.8/threading.py", line 932, in _bootstrap_inner
    self.run()
  File "/soft/datascience/conda/2022-07-19/mconda3/lib/python3.8/site-packages/wandb/sdk/internal/internal_util.py", line 51, in run
    self._run()
  File "/soft/datascience/conda/2022-07-19/mconda3/lib/python3.8/site-packages/wandb/sdk/internal/internal_util.py", line 102, in _run
    self._process(record)
  File "/soft/datascience/conda/2022-07-19/mconda3/lib/python3.8/site-packages/wandb/sdk/internal/internal.py", line 310, in _process
    self._sm.send(record)
  File "/soft/datascience/conda/2022-07-19/mconda3/lib/python3.8/site-packages/wandb/sdk/internal/sender.py", line 238, in send
    send_handler(record)
  File "/soft/datascience/conda/2022-07-19/mconda3/lib/python3.8/site-packages/wandb/sdk/internal/sender.py", line 250, in send_request
    logger.debug(f"send_request: {request_type}")
Message: 'send_request: stop_status'
Arguments: ()
--- Logging error ---
Traceback (most recent call last):
  File "/soft/datascience/conda/2022-07-19/mconda3/lib/python3.8/logging/__init__.py", line 1089, in emit
    self.flush()
  File "/soft/datascience/conda/2022-07-19/mconda3/lib/python3.8/logging/__init__.py", line 1069, in flush
    self.stream.flush()
OSError: [Errno 122] Disk quota exceeded
Call stack:
  File "/soft/datascience/conda/2022-07-19/mconda3/lib/python3.8/threading.py", line 890, in _bootstrap
    self._bootstrap_inner()
  File "/soft/datascience/conda/2022-07-19/mconda3/lib/python3.8/threading.py", line 932, in _bootstrap_inner
    self.run()
  File "/soft/datascience/conda/2022-07-19/mconda3/lib/python3.8/site-packages/wandb/sdk/internal/internal_util.py", line 51, in run
    self._run()
  File "/soft/datascience/conda/2022-07-19/mconda3/lib/python3.8/site-packages/wandb/sdk/internal/internal_util.py", line 102, in _run
    self._process(record)
  File "/soft/datascience/conda/2022-07-19/mconda3/lib/python3.8/site-packages/wandb/sdk/internal/internal.py", line 265, in _process
    self._hm.handle(record)
  File "/soft/datascience/conda/2022-07-19/mconda3/lib/python3.8/site-packages/wandb/sdk/internal/handler.py", line 132, in handle
    handler(record)
  File "/soft/datascience/conda/2022-07-19/mconda3/lib/python3.8/site-packages/wandb/sdk/internal/handler.py", line 140, in handle_request
    logger.debug(f"handle_request: {request_type}")
Message: 'handle_request: stop_status'
Arguments: ()
--- Logging error ---
Traceback (most recent call last):
  File "/soft/datascience/conda/2022-07-19/mconda3/lib/python3.8/logging/__init__.py", line 1089, in emit
    self.flush()
  File "/soft/datascience/conda/2022-07-19/mconda3/lib/python3.8/logging/__init__.py", line 1069, in flush
    self.stream.flush()
OSError: [Errno 122] Disk quota exceeded
Call stack:
  File "/soft/datascience/conda/2022-07-19/mconda3/lib/python3.8/threading.py", line 890, in _bootstrap
    self._bootstrap_inner()
  File "/soft/datascience/conda/2022-07-19/mconda3/lib/python3.8/threading.py", line 932, in _bootstrap_inner
    self.run()
  File "/soft/datascience/conda/2022-07-19/mconda3/lib/python3.8/site-packages/wandb/sdk/internal/internal_util.py", line 51, in run
    self._run()
  File "/soft/datascience/conda/2022-07-19/mconda3/lib/python3.8/site-packages/wandb/sdk/internal/internal_util.py", line 102, in _run
    self._process(record)
  File "/soft/datascience/conda/2022-07-19/mconda3/lib/python3.8/site-packages/wandb/sdk/internal/internal.py", line 310, in _process
    self._sm.send(record)
  File "/soft/datascience/conda/2022-07-19/mconda3/lib/python3.8/site-packages/wandb/sdk/internal/sender.py", line 238, in send
    send_handler(record)
  File "/soft/datascience/conda/2022-07-19/mconda3/lib/python3.8/site-packages/wandb/sdk/internal/sender.py", line 250, in send_request
    logger.debug(f"send_request: {request_type}")
Message: 'send_request: stop_status'
Arguments: ()
